Traceback (most recent call last):
  File "/home/lukem/anaconda3/lib/python3.11/site-packages/jupyter_cache/executors/utils.py", line 58, in single_nb_execution
    executenb(
  File "/home/lukem/anaconda3/lib/python3.11/site-packages/nbclient/client.py", line 1204, in execute
    return NotebookClient(nb=nb, resources=resources, km=km, **kwargs).execute()
           ^^^^^^^^^^^^^^^^^^^^^^^^^^^^^^^^^^^^^^^^^^^^^^^^^^^^^^^^^^^^^^^^^^^^^
  File "/home/lukem/anaconda3/lib/python3.11/site-packages/nbclient/util.py", line 84, in wrapped
    return just_run(coro(*args, **kwargs))
           ^^^^^^^^^^^^^^^^^^^^^^^^^^^^^^^
  File "/home/lukem/anaconda3/lib/python3.11/site-packages/nbclient/util.py", line 62, in just_run
    return loop.run_until_complete(coro)
           ^^^^^^^^^^^^^^^^^^^^^^^^^^^^^
  File "/home/lukem/anaconda3/lib/python3.11/asyncio/base_events.py", line 653, in run_until_complete
    return future.result()
           ^^^^^^^^^^^^^^^
  File "/home/lukem/anaconda3/lib/python3.11/site-packages/nbclient/client.py", line 663, in async_execute
    await self.async_execute_cell(
  File "/home/lukem/anaconda3/lib/python3.11/site-packages/nbclient/client.py", line 965, in async_execute_cell
    await self._check_raise_for_error(cell, cell_index, exec_reply)
  File "/home/lukem/anaconda3/lib/python3.11/site-packages/nbclient/client.py", line 862, in _check_raise_for_error
    raise CellExecutionError.from_cell_and_msg(cell, exec_reply_content)
nbclient.exceptions.CellExecutionError: An error occurred while executing the following cell:
------------------
import xarray as xr
netcdf_file = ''
xrds = xr.open_dataset(netcdf_file)
print(xrds)
------------------

[0;31m---------------------------------------------------------------------------[0m
[0;31mValueError[0m                                Traceback (most recent call last)
Cell [0;32mIn[1], line 3[0m
[1;32m      1[0m [38;5;28;01mimport[39;00m [38;5;21;01mxarray[39;00m [38;5;28;01mas[39;00m [38;5;21;01mxr[39;00m
[1;32m      2[0m netcdf_file [38;5;241m=[39m [38;5;124m'[39m[38;5;124m'[39m
[0;32m----> 3[0m xrds [38;5;241m=[39m xr[38;5;241m.[39mopen_dataset(netcdf_file)
[1;32m      4[0m [38;5;28mprint[39m(xrds)

File [0;32m~/anaconda3/lib/python3.11/site-packages/xarray/backends/api.py:547[0m, in [0;36mopen_dataset[0;34m(filename_or_obj, engine, chunks, cache, decode_cf, mask_and_scale, decode_times, decode_timedelta, use_cftime, concat_characters, decode_coords, drop_variables, inline_array, chunked_array_type, from_array_kwargs, backend_kwargs, **kwargs)[0m
[1;32m    544[0m     kwargs[38;5;241m.[39mupdate(backend_kwargs)
[1;32m    546[0m [38;5;28;01mif[39;00m engine [38;5;129;01mis[39;00m [38;5;28;01mNone[39;00m:
[0;32m--> 547[0m     engine [38;5;241m=[39m plugins[38;5;241m.[39mguess_engine(filename_or_obj)
[1;32m    549[0m [38;5;28;01mif[39;00m from_array_kwargs [38;5;129;01mis[39;00m [38;5;28;01mNone[39;00m:
[1;32m    550[0m     from_array_kwargs [38;5;241m=[39m {}

File [0;32m~/anaconda3/lib/python3.11/site-packages/xarray/backends/plugins.py:197[0m, in [0;36mguess_engine[0;34m(store_spec)[0m
[1;32m    189[0m [38;5;28;01melse[39;00m:
[1;32m    190[0m     error_msg [38;5;241m=[39m (
[1;32m    191[0m         [38;5;124m"[39m[38;5;124mfound the following matches with the input file in xarray[39m[38;5;124m'[39m[38;5;124ms IO [39m[38;5;124m"[39m
[1;32m    192[0m         [38;5;124mf[39m[38;5;124m"[39m[38;5;124mbackends: [39m[38;5;132;01m{[39;00mcompatible_engines[38;5;132;01m}[39;00m[38;5;124m. But their dependencies may not be installed, see:[39m[38;5;130;01m\n[39;00m[38;5;124m"[39m
[1;32m    193[0m         [38;5;124m"[39m[38;5;124mhttps://docs.xarray.dev/en/stable/user-guide/io.html [39m[38;5;130;01m\n[39;00m[38;5;124m"[39m
[1;32m    194[0m         [38;5;124m"[39m[38;5;124mhttps://docs.xarray.dev/en/stable/getting-started-guide/installing.html[39m[38;5;124m"[39m
[1;32m    195[0m     )
[0;32m--> 197[0m [38;5;28;01mraise[39;00m [38;5;167;01mValueError[39;00m(error_msg)

[0;31mValueError[0m: did not find a match in any of xarray's currently installed IO backends ['netcdf4', 'scipy']. Consider explicitly selecting one of the installed engines via the ``engine`` parameter, or installing additional IO dependencies, see:
https://docs.xarray.dev/en/stable/getting-started-guide/installing.html
https://docs.xarray.dev/en/stable/user-guide/io.html
ValueError: did not find a match in any of xarray's currently installed IO backends ['netcdf4', 'scipy']. Consider explicitly selecting one of the installed engines via the ``engine`` parameter, or installing additional IO dependencies, see:
https://docs.xarray.dev/en/stable/getting-started-guide/installing.html
https://docs.xarray.dev/en/stable/user-guide/io.html

